Workbook

Sheet mcantu_STRU_BRBacklog_20260128_
A1: OrderDate | B1: RequestedShipDate | C1: ScheduledShipDate | D1: PromisedShipDate | E1: SONumber | F1: LineNumber | G1: ShipToCode | H1: ItemCode | I1: ItemDescription | J1: OrderQuantity | K1: UnitPrice | L1: ExtendedLineAmount | M1: CustomerCode | N1: ItemSalesClassCode | O1: DropShip | P1: SOTypeCode | Q1: FinalDestination | R1: CustomerName | S1: ShipToAddress1 | T1: ShipToAddress2 | U1: ShipToStateCode | V1: ShipToZip | W1: ParentDocumentNumber | X1: Weight | Y1: OrderMessage | Z1: ShipToName | AA1: ShipToCity | AB1: ShippingInstructions | AC1: WarehouseCode | AD1: WarehouseName
A2: 45944 | B2: 46034 | C2: 2 | D2: 46050 | E2: 0000064684 | F2: 1 | G2: MAYNARD | H2: 003843 | I2: DeRoyal Episeal Tan 3 Inch Non-Reinforced Material | J2: 28000 | K2: 0.396 | L2: 11088 | M2: DEROYAL | N2: MEDICAL | O2: FALSE | P2: SO | R2: DeRoyal Accounts Payable Dept | S2: 185 Richardson Way | U2: TN | V2: 37807 | X2: 0 | Z2: DeRoyal Foam/ Convertin | AA2: Maynardville | AC2: PCI-01 | AD2: STRUKMYER, LLC
A3: 45974 | B3: 45996 | C3: 2 | D3: 2 | E3: 0000064757 | F3: 2 | G3: LAND | H3: 006370 | I3: TB DRY MOUTH TINGLING RINSE 16 OZ BULK 40101908 | J3: 20000 | K3: 1.7789 | L3: 35578 | M3: ORORA | N3: Filling OP | O3: FALSE | P3: SO | R3: Orora Business Service Center | S3: 13397 Marlay Ave Ste A | U3: CA | V3: 92337-6946 | X3: 0 | Z3: Landsberg-Fullfillment Solutions | AA3: Fontana | AB3: Need special certificate COA before shipped | AC3: PCI-01 | AD3: STRUKMYER, LLC
A4: 46020 | B4: 46089 | C4: 2 | D4: 2 | E4: 0000064846 | F4: 1 | G4: lawson | H4: 005121 | I4: IMPLUS CANADA BLISTER PADS 4740700 | J4: 15600 | K4: 2.9 | L4: 45240 | M4: IMPLUS CAN | N4: MEDICAL | O4: FALSE | P4: SO | R4: Implus Canada | S4: 8399 LAWSON ROAD, UNIT 104 | U4: ON | V4: L9T9L1 | X4: 0 | Z4: SPENCO CANADA/IMPLUS CANADA | AA4: MILTON | AB4: For all Collect shipments to Implus Canada email Graham Patterson gpatterson@4implus.com, Shipments@4implus.com, and our Canadian carrier One For Freight support team at Implus@oneforfreight.com.
A5: Please include the following information: PO # | B5: pallet count | C5: pallet dims & weights | D5: product NMFC | E5: freight class | F5: ship from address | G5: pickup hours | H5: ship to location.
A7: PCI-01 STRUKMYER | B7: LLC"
A8: 46042 | B8: 2 | C8: 2 | D8: 2 | E8: 0000064923 | F8: 1 | H8: N-4001 | I8: 1,000 L Obelix Bulk Wound Wash Solution | J8: 1 | K8: 2912 | L8: 2912 | M8: URGO | N8: MEDICAL | O8: FALSE | P8: SO | R8: URGO Medical | S8: 100 Lexington Street, Suite 400 | U8: TX | V8: 76102 | X8: 0 | Z8: URGO Medical | AA8: Fort Worth | AC8: PCI-01 | AD8: STRUKMYER, LLC
A9: 46057 | B9: 2 | C9: 2 | D9: 2 | E9: 0000064956 | F9: 1 | G9: BILL | H9: 007217 | I9: DERMACLIP EXT 3 CLIP PAD NS -31005 | J9: 300 | K9: 6.7991 | L9: 2039.73 | M9: Dermaclip | N9: MEDICAL | O9: FALSE | P9: SO | R9: DermaClip US, LLC | S9: 730 N Post Oak Rd., Ste. 202 | U9: TX | V9: 77024 | X9: 0 | Z9: DermaClip US, LLC | AA9: Houston | AC9: PCI-01 | AD9: STRUKMYER, LLC
A10: 46064 | B10: 2 | C10: 2 | D10: 2 | E10: 0000064985 | F10: 1 | H10: N-4001 | I10: Cleaning validation for Delight production | J10: 1 | K10: 3000 | L10: 3000 | M10: Bloomi | N10: MEDICAL | O10: FALSE | P10: SO | R10: The Bloomi Inc | S10: 74 Royal Ridge Ct | U10: CA | V10: 94507 | X10: 0 | Z10: The Bloomi Inc | AA10: Alamo | AC10: PCI-01 | AD10: STRUKMYER, LLC
A11: 46064 | B11: 2 | C11: 2 | D11: 2 | E11: 0000064986 | F11: 1 | H11: 007991 | I11: Bloomi Delight 3oz | J11: 5000 | K11: 3.45 | L11: 17250 | M11: Bloomi | N11: Default | O11: FALSE | P11: SO | R11: The Bloomi Inc | S11: 74 Royal Ridge Ct | U11: CA | V11: 94507 | X11: 0 | Z11: The Bloomi Inc | AA11: Alamo | AB11: Bloomi to arrange freight | AC11: PCI-01 | AD11: STRUKMYER, LLC
A12: 46064 | B12: 46108 | C12: 2 | D12: 2 | E12: 0000064990 | F12: 1 | H12: 007993 | I12: 200 RC Filter | J12: 10000 | K12: 1.675 | L12: 16750 | M12: HARM IRE | N12: MEDICAL | O12: FALSE | P12: SO | R12: Harmac Medical Products | S12: IDA Business Park | U12: .. | V12: ... | X12: 0 | Z12: Harmac Medical Products | AA12: Castlerea, County Roscommon | AC12: PCI-01 | AD12: STRUKMYER, LLC
A13: 46064 | B13: 46108 | C13: 2 | D13: 2 | E13: 0000064990 | F13: 2 | H13: 007992 | I13: Port Drape | J13: 10000 | K13: 0.625 | L13: 6250 | M13: HARM IRE | N13: MEDICAL | O13: FALSE | P13: SO | R13: Harmac Medical Products | S13: IDA Business Park | U13: .. | V13: ... | X13: 0 | Z13: Harmac Medical Products | AA13: Castlerea, County Roscommon | AC13: PCI-01 | AD13: STRUKMYER, LLC
A14: 46066 | B14: 2 | C14: 2 | D14: 2 | E14: 0000064992 | F14: 1 | G14: BILL | H14: 008012 | I14: Bloomi Delight 3oz (1K Use Only) | J14: 1 | K14: 1000 | L14: 1000 | M14: Bloomi | N14: Filling OP | O14: FALSE | P14: SO | R14: The Bloomi Inc | S14: 74 Royal Ridge Ct | U14: CA | V14: 94507 | X14: 0 | Z14: The Bloomi Inc | AA14: Alamo | AC14: PCI-01 | AD14: STRUKMYER, LLC
A15: 46071 | B15: 2 | C15: 2 | D15: 2 | E15: 0000065007 | F15: 1 | H15: N-4001 | I15: 1 of 3 Bulk Validations | J15: 1 | K15: 1910 | L15: 1910 | M15: TURN | N15: MEDICAL | O15: FALSE | P15: SO | R15: Turn Therapeutics | S15: 250 N. Westlake Blvd, Suite 210 | U15: CA | V15: 91362 | X15: 0 | Z15: Turn Therapeutics | AA15: Westlake Village | AC15: PCI-01 | AD15: STRUKMYER, LLC
A16: 46071 | B16: 2 | C16: 2 | D16: 2 | E16: 0000065007 | F16: 2 | H16: 007997 | I16: Turn Therapeutics Hexagen Bulk - 55 Gallon Drum | J16: 8 | K16: 1910 | L16: 15280 | M16: TURN | N16: Filling OP | O16: FALSE | P16: SO | R16: Turn Therapeutics | S16: 250 N. Westlake Blvd, Suite 210 | U16: CA | V16: 91362 | X16: 0 | Z16: Turn Therapeutics | AA16: Westlake Village | AC16: PCI-01 | AD16: STRUKMYER, LLC
A17: 46071 | B17: 2 | C17: 2 | D17: 2 | E17: 0000065007 | F17: 3 | H17: N-4001 | I17: Cleaning Validation | J17: 1 | K17: 10000 | L17: 10000 | M17: TURN | N17: MEDICAL | O17: FALSE | P17: SO | R17: Turn Therapeutics | S17: 250 N. Westlake Blvd, Suite 210 | U17: CA | V17: 91362 | X17: 0 | Z17: Turn Therapeutics | AA17: Westlake Village | AC17: PCI-01 | AD17: STRUKMYER, LLC
A18: 46076 | B18: 46191 | C18: 2 | D18: 2 | E18: 0000065010 | F18: 1 | G18: ATLANTA | H18: 007488 | I18: CARDINAL HEALTH TELFA NON-ADHERENT DRESSING 3"x4" 2132 | J18: 1080 | K18: 170.4 | L18: 184032 | M18: COVIDMA | N18: MEDICAL | O18: FALSE | P18: SO | R18: Patient Recovery | S18: 110 Kendall Park Lane | U18: GA | V18: 30336 | X18: 0 | Z18: Atlanta RC - US | AA18: Atlanta | AB18: **Effective 7/28/18 www.routingguides.com/cardinal%20health
A19: For Small orders and LTL use fedex 3rd party 920710310 | B19: less than or equal to 150lbs | C19: refer to LTL/TL routing guide *requires special cert*" | D19: PCI-01 | E19: STRUKMYER, LLC
A20: 46077 | B20: 46225 | C20: 2 | D20: 2 | E20: 0000065011 | F20: 1 | G20: G-Global | H20: 000609 | I20: MEDISTRIP 1/4 IN X 3 IN BULK | J20: 17 | K20: 119 | L20: 2023 | M20: CENTURION | N20: MEDICAL | O20: FALSE | P20: SO | R20: Centurion Medical Products Corp | S20: C/O G-Global Logistics Inc | T20: 1776 Pan American St. Building B Suite 100 | U20: CA | V20: 92231 | X20: 1 | Z20: Centurion Medical | AA20: Calexico | AC20: PCI-01 | AD20: STRUKMYER, LLC
A21: 46077 | B21: 46225 | C21: 2 | D21: 2 | E21: 0000065011 | F21: 2 | G21: G-Global | H21: 000610 | I21: MEDISTRIP 1 IN X 4 IN BULK | J21: 55 | K21: 196.5 | L21: 10807.5 | M21: CENTURION | N21: MEDICAL | O21: FALSE | P21: SO | R21: Centurion Medical Products Corp | S21: C/O G-Global Logistics Inc | T21: 1776 Pan American St. Building B Suite 100 | U21: CA | V21: 92231 | X21: 4 | Z21: Centurion Medical | AA21: Calexico | AC21: PCI-01 | AD21: STRUKMYER, LLC
A22: 46077 | B22: 46176 | C22: 2 | D22: 2 | E22: 0000065012 | F22: 1 | G22: G-Global | H22: 002977 | I22: MEDLINE DRSG SURESITE 4.75 X 4 FRAME/LABL (MSC52281) | J22: 63 | K22: 340 | L22: 21420 | M22: CENTURION | N22: MEDICAL | O22: FALSE | P22: SO | R22: Centurion Medical Products Corp | S22: C/O G-Global Logistics Inc | T22: 1776 Pan American St. Building B Suite 100 | U22: CA | V22: 92231 | X22: 26 | Z22: Centurion Medical | AA22: Calexico | AC22: PCI-01 | AD22: STRUKMYER, LLC
A23: 46077 | B23: 46105 | C23: 2 | D23: 2 | E23: 0000065013 | F23: 1 | H23: 007861 | I23: ViaCLYR Flip Top 8oz | J23: 5000 | K23: 2.7 | L23: 13500 | M23: CLYRA | N23: Filling OP | O23: FALSE | P23: SO | R23: Clyra Medical Technologies, Inc. | S23: 10770 N 46th Street, Unit C-300 | U23: FL | V23: 33617 | X23: 0 | Z23: Clyra Medical Technologies, Inc. | AA23: Tampa | AC23: PCI-01 | AD23: STRUKMYER, LLC
A24: 46077 | B24: 46105 | C24: 2 | D24: 2 | E24: 0000065013 | F24: 2 | H24: 007862 | I24: ViaCLYR Flip Top 16oz | J24: 5000 | K24: 3.5 | L24: 17500 | M24: CLYRA | N24: Filling OP | O24: FALSE | P24: SO | R24: Clyra Medical Technologies, Inc. | S24: 10770 N 46th Street, Unit C-300 | U24: FL | V24: 33617 | X24: 0 | Z24: Clyra Medical Technologies, Inc. | AA24: Tampa | AC24: PCI-01 | AD24: STRUKMYER, LLC
A25: 46077 | B25: 46105 | C25: 2 | D25: 2 | E25: 0000065013 | F25: 3 | H25: 007863 | I25: ViaCLYR Flip Top 32oz | J25: 1000 | K25: 7.52 | L25: 7520 | M25: CLYRA | N25: Filling OP | O25: FALSE | P25: SO | R25: Clyra Medical Technologies, Inc. | S25: 10770 N 46th Street, Unit C-300 | U25: FL | V25: 33617 | X25: 0 | Z25: Clyra Medical Technologies, Inc. | AA25: Tampa | AC25: PCI-01 | AD25: STRUKMYER, LLC
A26: 46077 | B26: 46237 | C26: 2 | D26: 2 | E26: 0000065014 | F26: 1 | G26: 3440 | H26: 005045 | I26: FREUDENBERG 30cm X 47cm Nonwoven Sheets 122P0463 | J26: 25000 | K26: 1.63 | L26: 40750 | M26: FREUD | N26: MEDICAL | O26: FALSE | P26: SO | R26: Freudenberg Performance Materials LP | S26: 3440 Industrial Drive | U26: NC | V26: 27704 | X26: 0 | Z26: Freudenberg Performance Materials LP | AA26: Durham | AB26: **DO NOT DOUBLE STACK LABEL - TAKE PHOTO**
A27: SHIP VIA CH ROBINSON. CONTACT Dustin Seong 813-840-4526 OR dustin.seong@chrobinson.com. Freight is 3rd party bill to Freudenberg
A28: Receiving hours M-F 8am -4pm
A29: PCI-01 STRUKMYER | B29: LLC"
A30: 45903 | B30: 2 | C30: 46063 | D30: 46021 | E30: 0000064540 | F30: 1 | H30: 007898 | I30: MPM DryMax/DrySAP Extra Super Absorbent Drsg, Sterile, 8X8; | J30: 10000 | K30: 0.99 | L30: 9900 | M30: MPM | N30: MEDICAL | O30: FALSE | P30: SO | R30: MPM Medical, Inc. | S30: 1801 Big Town Blvd, Suite 300 | U30: TX | V30: 75149 | X30: 0 | Z30: MPM Medical, Inc. | AA30: Mesquite | AC30: PCI-01 | AD30: STRUKMYER, LLC
A31: 45987 | B31: 46104 | C31: 46073 | D31: 46086 | E31: 0000064784 | F31: 2 | G31: ICS | H31: 007153 | I31: URGO - VASHE 250 ml Flip Top 00313 | J31: 50004 | K31: 1.88 | L31: 94007.52 | M31: URGO | N31: Filling OP | O31: FALSE | P31: SO | R31: URGO Medical | S31: 167 International Blvd, Suite 550 | U31: KY | V31: 40109 | X31: 0 | Z31: ICS (Urgo Medical) | AA31: Brooks | AB31: ReceivingBrooks@icsconnect.com
A32: 502-955-3671" | B32: PCI-01 | C32: STRUKMYER, LLC
A33: 45987 | B33: 46118 | C33: 46073 | D33: 46086 | E33: 0000064786 | F33: 1 | G33: ICS | H33: 007153 | I33: URGO - VASHE 250 ml Flip Top 00313 | J33: 45000 | K33: 1.88 | L33: 84600 | M33: URGO | N33: Filling OP | O33: FALSE | P33: SO | R33: URGO Medical | S33: 167 International Blvd, Suite 550 | U33: KY | V33: 40109 | X33: 0 | Z33: ICS (Urgo Medical) | AA33: Brooks | AB33: ReceivingBrooks@icsconnect.com
A34: 502-955-3671" | B34: PCI-01 | C34: STRUKMYER, LLC
A35: 45987 | B35: 46125 | C35: 46073 | D35: 46086 | E35: 0000064787 | F35: 1 | G35: ICS | H35: 007153 | I35: URGO - VASHE 250 ml Flip Top 00313 | J35: 50004 | K35: 1.88 | L35: 94007.52 | M35: URGO | N35: Filling OP | O35: FALSE | P35: SO | R35: URGO Medical | S35: 167 International Blvd, Suite 550 | U35: KY | V35: 40109 | X35: 0 | Z35: ICS (Urgo Medical) | AA35: Brooks | AB35: ReceivingBrooks@icsconnect.com
A36: 502-955-3671" | B36: PCI-01 | C36: STRUKMYER, LLC
A37: 45974 | B37: 45996 | C37: 46076 | D37: 46064 | E37: 0000064757 | F37: 1 | G37: LAND | H37: 006370 | I37: TB DRY MOUTH TINGLING RINSE 16 OZ BULK 40101908 | J37: 17475 | K37: 1.7789 | L37: 31086.28 | M37: ORORA | N37: Filling OP | O37: FALSE | P37: SO | R37: Orora Business Service Center | S37: 13397 Marlay Ave Ste A | U37: CA | V37: 92337-6946 | X37: 0 | Z37: Landsberg-Fullfillment Solutions | AA37: Fontana | AB37: Need special certificate COA before shipped | AC37: PCI-01 | AD37: STRUKMYER, LLC
A38: 45987 | B38: 46097 | C38: 46077 | D38: 46090 | E38: 0000064788 | F38: 1 | G38: ICS | H38: 007154 | I38: URGO - VASHE 475 ml Flip Top 00314 | J38: 30000 | K38: 2.59 | L38: 77700 | M38: URGO | N38: Filling OP | O38: FALSE | P38: SO | R38: URGO Medical | S38: 167 International Blvd, Suite 550 | U38: KY | V38: 40109 | X38: 0 | Z38: ICS (Urgo Medical) | AA38: Brooks | AB38: ReceivingBrooks@icsconnect.com
A39: 502-955-3671" | B39: PCI-01 | C39: STRUKMYER, LLC
A40: 45594 | B40: 45685 | C40: 46078 | D40: 45709 | E40: 0000063455 | F40: 30 | G40: C02 | H40: 006011 | I40: MEDLINE CURAD MEDISTRIP 1/4 X 4 IN STERILE NON250414 | J40: 182 | K40: 127.14 | L40: 23139.48 | M40: MEDL | N40: MEDICAL | O40: FALSE | P40: SO | R40: Medline Industries, Inc. | S40: 2200 Cornerstone Pkwy, Ste 100 | U40: IL | V40: 60030 | X40: 0 | Z40: Medline Industries LP | AA40: Grayslake | AC40: PCI-01 | AD40: STRUKMYER, LLC
A41: 45618 | B41: 45709 | C41: 46078 | D41: 45709 | E41: 0000063558 | F41: 10 | G41: B25 | H41: 006011 | I41: MEDLINE CURAD MEDISTRIP 1/4 X 4 IN STERILE NON250414 | J41: 26 | K41: 127.14 | L41: 3305.64 | M41: MEDL | N41: MEDICAL | O41: FALSE | P41: SO | R41: Medline Industries, Inc. | S41: 1401 N. Universal Ave. | U41: MO | V41: 641202139 | X41: 0 | Z41: Medline Industries LP | AA41: KANSAS CITY | AC41: PCI-01 | AD41: STRUKMYER, LLC
...

Sheet Raw data w lookup
L2: =SUBTOTAL(9, L4:L1452) -> 9065728.6
A3: Order date | B3: Requested Ship date | C3: ScheduledShipDate | D3: PromisedShipDate | E3: SONumber | F3: LineNumber | G3: ShipToCode | H3: ItemCode | I3: ItemDescription | J3: OrderQuantity | K3: UnitPrice | L3: ExtendedLineAmount | M3: CustomerCode | N3: ItemSalesClassCode | O3: DropShip | P3: SOTypeCode | Q3: FinalDestination | R3: CustomerName | S3: ShipToAddress1 | T3: ShipToAddress2 | U3: ShipToStateCode | V3: ShipToZip | W3: ParentDocumentNumber | X3: Weight | Y3: OrderMessage | Z3: ShipToName | AA3: ShipToCity | AB3: ShippingInstructions | AC3: WarehouseCode | AD3: WarehouseName | AE3: Profit
A4: 45944 | B4: 46034 | C4: 2 | D4: 46050 | E4: 0000064684 | F4: 1 | G4: MAYNARD | H4: 3843 | I4: DeRoyal Episeal Tan 3 Inch Non-Reinforced Material | J4: 28000 | K4: 0.396 | L4: 11088 | M4: DEROYAL | N4: MEDICAL | O4: FALSE | P4: SO | R4: DeRoyal Accounts Payable Dept | S4: 185 Richardson Way | U4: TN | V4: 37807 | X4: 0 | Z4: DeRoyal Foam/ Convertin | AA4: Maynardville | AC4: PCI-01 | AE4: =J4*VLOOKUP(H4,'Cost sheet'!$C$2:$G$1232,5,FALSE) -> 7710.752
A5: 45974 | B5: 45996 | C5: 2 | D5: 2 | E5: 0000064757 | F5: 2 | G5: LAND | H5: 6370 | I5: TB DRY MOUTH TINGLING RINSE 16 OZ BULK 40101908 | J5: 20000 | K5: 1.7789 | L5: 35578 | M5: ORORA | N5: Filling OP | O5: FALSE | P5: SO | R5: Orora Business Service Center | S5: 13397 Marlay Ave Ste A | U5: CA | V5: 92337-6946 | X5: 0 | Z5: Landsberg-Fullfillment Solutions | AA5: Fontana | AB5: Need special certificate COA before shipped | AC5: PCI-01 | AE5: =J5*VLOOKUP(H5,'Cost sheet'!$C$2:$G$1232,5,FALSE) -> 13112.86
A6: 46020 | B6: 46089 | C6: 2 | D6: 2 | E6: 0000064846 | F6: 1 | G6: lawson | H6: 5121 | I6: IMPLUS CANADA BLISTER PADS 4740700 | J6: 15600 | K6: 2.9 | L6: 45240 | M6: IMPLUS CAN | N6: MEDICAL | O6: FALSE | P6: SO | R6: Implus Canada | S6: 8399 LAWSON ROAD, UNIT 104 | U6: ON | V6: L9T9L1 | X6: 0 | Z6: SPENCO CANADA/IMPLUS CANADA | AA6: MILTON | AB6: For all Collect shipments to Implus Canada email Graham Patterson gpatterson@4implus.com, Shipments@4implus.com, and our Canadian carrier One For Freight support team at Implus@oneforfreight.com. | AE6: =J6*VLOOKUP(H6,'Cost sheet'!$C$2:$G$1232,5,FALSE) -> 19753.25
A7: 46042 | B7: 2 | C7: 2 | D7: 2 | E7: 0000064923 | F7: 1 | H7: N-4001 | I7: 1,000 L Obelix Bulk Wound Wash Solution | J7: 1 | K7: 2912 | L7: 2912 | M7: URGO | N7: MEDICAL | O7: FALSE | P7: SO | R7: URGO Medical | S7: 100 Lexington Street, Suite 400 | U7: TX | V7: 76102 | X7: 0 | Z7: URGO Medical | AA7: Fort Worth | AC7: PCI-01 | AE7: =J7*VLOOKUP(H7,'Cost sheet'!$C$2:$G$1232,5,FALSE) -> #N/A
A8: 46057 | B8: 2 | C8: 2 | D8: 2 | E8: 0000064956 | F8: 1 | G8: BILL | H8: 7217 | I8: DERMACLIP EXT 3 CLIP PAD NS -31005 | J8: 300 | K8: 6.7991 | L8: 2039.73 | M8: Dermaclip | N8: MEDICAL | O8: FALSE | P8: SO | R8: DermaClip US, LLC | S8: 730 N Post Oak Rd., Ste. 202 | U8: TX | V8: 77024 | X8: 0 | Z8: DermaClip US, LLC | AA8: Houston | AC8: PCI-01 | AE8: =J8*VLOOKUP(H8,'Cost sheet'!$C$2:$G$1232,5,FALSE) -> 125.9112
A9: 46064 | B9: 2 | C9: 2 | D9: 2 | E9: 0000064985 | F9: 1 | H9: N-4001 | I9: Cleaning validation for Delight production | J9: 1 | K9: 3000 | L9: 3000 | M9: Bloomi | N9: MEDICAL | O9: FALSE | P9: SO | R9: The Bloomi Inc | S9: 74 Royal Ridge Ct | U9: CA | V9: 94507 | X9: 0 | Z9: The Bloomi Inc | AA9: Alamo | AC9: PCI-01 | AE9: =J9*VLOOKUP(H9,'Cost sheet'!$C$2:$G$1232,5,FALSE) -> #N/A
A10: 46064 | B10: 2 | C10: 2 | D10: 2 | E10: 0000064986 | F10: 1 | H10: 7991 | I10: Bloomi Delight 3oz | J10: 5000 | K10: 3.45 | L10: 17250 | M10: Bloomi | N10: Default | O10: FALSE | P10: SO | R10: The Bloomi Inc | S10: 74 Royal Ridge Ct | U10: CA | V10: 94507 | X10: 0 | Z10: The Bloomi Inc | AA10: Alamo | AB10: Bloomi to arrange freight | AC10: PCI-01 | AE10: =J10*VLOOKUP(H10,'Cost sheet'!$C$2:$G$1232,5,FALSE) -> 17250
A11: 46064 | B11: 46108 | C11: 2 | D11: 2 | E11: 0000064990 | F11: 1 | H11: 7993 | I11: 200 RC Filter | J11: 10000 | K11: 1.675 | L11: 16750 | M11: HARM IRE | N11: MEDICAL | O11: FALSE | P11: SO | R11: Harmac Medical Products | S11: IDA Business Park | U11: .. | V11: ... | X11: 0 | Z11: Harmac Medical Products | AA11: Castlerea, County Roscommon | AC11: PCI-01 | AE11: =J11*VLOOKUP(H11,'Cost sheet'!$C$2:$G$1232,5,FALSE) -> 16750
A12: 46064 | B12: 46108 | C12: 2 | D12: 2 | E12: 0000064990 | F12: 2 | H12: 7992 | I12: Port Drape | J12: 10000 | K12: 0.625 | L12: 6250 | M12: HARM IRE | N12: MEDICAL | O12: FALSE | P12: SO | R12: Harmac Medical Products | S12: IDA Business Park | U12: .. | V12: ... | X12: 0 | Z12: Harmac Medical Products | AA12: Castlerea, County Roscommon | AC12: PCI-01 | AE12: =J12*VLOOKUP(H12,'Cost sheet'!$C$2:$G$1232,5,FALSE) -> 5600
A13: 46066 | B13: 2 | C13: 2 | D13: 2 | E13: 0000064992 | F13: 1 | G13: BILL | H13: 8012 | I13: Bloomi Delight 3oz (1K Use Only) | J13: 1 | K13: 1000 | L13: 1000 | M13: Bloomi | N13: Filling OP | O13: FALSE | P13: SO | R13: The Bloomi Inc | S13: 74 Royal Ridge Ct | U13: CA | V13: 94507 | X13: 0 | Z13: The Bloomi Inc | AA13: Alamo | AC13: PCI-01 | AE13: =J13*VLOOKUP(H13,'Cost sheet'!$C$2:$G$1232,5,FALSE) -> 999.26485
A14: 46071 | B14: 2 | C14: 2 | D14: 2 | E14: 0000065007 | F14: 1 | H14: N-4001 | I14: 1 of 3 Bulk Validations | J14: 1 | K14: 1910 | L14: 1910 | M14: TURN | N14: MEDICAL | O14: FALSE | P14: SO | R14: Turn Therapeutics | S14: 250 N. Westlake Blvd, Suite 210 | U14: CA | V14: 91362 | X14: 0 | Z14: Turn Therapeutics | AA14: Westlake Village | AC14: PCI-01 | AE14: =J14*VLOOKUP(H14,'Cost sheet'!$C$2:$G$1232,5,FALSE) -> #N/A
A15: 46071 | B15: 2 | C15: 2 | D15: 2 | E15: 0000065007 | F15: 2 | H15: 7997 | I15: Turn Therapeutics Hexagen Bulk - 55 Gallon Drum | J15: 8 | K15: 1910 | L15: 15280 | M15: TURN | N15: Filling OP | O15: FALSE | P15: SO | R15: Turn Therapeutics | S15: 250 N. Westlake Blvd, Suite 210 | U15: CA | V15: 91362 | X15: 0 | Z15: Turn Therapeutics | AA15: Westlake Village | AC15: PCI-01 | AE15: =J15*VLOOKUP(H15,'Cost sheet'!$C$2:$G$1232,5,FALSE) -> 15280
A16: 46071 | B16: 2 | C16: 2 | D16: 2 | E16: 0000065007 | F16: 3 | H16: N-4001 | I16: Cleaning Validation | J16: 1 | K16: 10000 | L16: 10000 | M16: TURN | N16: MEDICAL | O16: FALSE | P16: SO | R16: Turn Therapeutics | S16: 250 N. Westlake Blvd, Suite 210 | U16: CA | V16: 91362 | X16: 0 | Z16: Turn Therapeutics | AA16: Westlake Village | AC16: PCI-01 | AE16: =J16*VLOOKUP(H16,'Cost sheet'!$C$2:$G$1232,5,FALSE) -> #N/A
A17: 46076 | B17: 46191 | C17: 2 | D17: 2 | E17: 0000065010 | F17: 1 | G17: ATLANTA | H17: 7488 | I17: CARDINAL HEALTH TELFA NON-ADHERENT DRESSING 3"x4" 2132 | J17: 1080 | K17: 170.4 | L17: 184032 | M17: COVIDMA | N17: MEDICAL | O17: FALSE | P17: SO | R17: Patient Recovery | S17: 110 Kendall Park Lane | U17: GA | V17: 30336 | X17: 0 | Z17: Atlanta RC - US | AA17: Atlanta | AB17: **Effective 7/28/18 www.routingguides.com/cardinal%20health | AE17: =J17*VLOOKUP(H17,'Cost sheet'!$C$2:$G$1232,5,FALSE) -> 21385.04
A18: 46077 | B18: 46225 | C18: 2 | D18: 2 | E18: 0000065011 | F18: 1 | G18: G-Global | H18: 609 | I18: MEDISTRIP 1/4 IN X 3 IN BULK | J18: 17 | K18: 119 | L18: 2023 | M18: CENTURION | N18: MEDICAL | O18: FALSE | P18: SO | R18: Centurion Medical Products Corp | S18: C/O G-Global Logistics Inc | T18: 1776 Pan American St. Building B Suite 100 | U18: CA | V18: 92231 | X18: 1 | Z18: Centurion Medical | AA18: Calexico | AC18: PCI-01 | AE18: =J18*VLOOKUP(H18,'Cost sheet'!$C$2:$G$1232,5,FALSE) -> 844.04779
A19: 46077 | B19: 46225 | C19: 2 | D19: 2 | E19: 0000065011 | F19: 2 | G19: G-Global | H19: 610 | I19: MEDISTRIP 1 IN X 4 IN BULK | J19: 55 | K19: 196.5 | L19: 10807.5 | M19: CENTURION | N19: MEDICAL | O19: FALSE | P19: SO | R19: Centurion Medical Products Corp | S19: C/O G-Global Logistics Inc | T19: 1776 Pan American St. Building B Suite 100 | U19: CA | V19: 92231 | X19: 4 | Z19: Centurion Medical | AA19: Calexico | AC19: PCI-01 | AE19: =J19*VLOOKUP(H19,'Cost sheet'!$C$2:$G$1232,5,FALSE) -> 4062.229
A20: 46077 | B20: 46176 | C20: 2 | D20: 2 | E20: 0000065012 | F20: 1 | G20: G-Global | H20: 2977 | I20: MEDLINE DRSG SURESITE 4.75 X 4 FRAME/LABL (MSC52281) | J20: 63 | K20: 340 | L20: 21420 | M20: CENTURION | N20: MEDICAL | O20: FALSE | P20: SO | R20: Centurion Medical Products Corp | S20: C/O G-Global Logistics Inc | T20: 1776 Pan American St. Building B Suite 100 | U20: CA | V20: 92231 | X20: 26 | Z20: Centurion Medical | AA20: Calexico | AC20: PCI-01 | AE20: =J20*VLOOKUP(H20,'Cost sheet'!$C$2:$G$1232,5,FALSE) -> 5391.365
A21: 46077 | B21: 46105 | C21: 2 | D21: 2 | E21: 0000065013 | F21: 1 | H21: 7861 | I21: ViaCLYR Flip Top 8oz | J21: 5000 | K21: 2.7 | L21: 13500 | M21: CLYRA | N21: Filling OP | O21: FALSE | P21: SO | R21: Clyra Medical Technologies, Inc. | S21: 10770 N 46th Street, Unit C-300 | U21: FL | V21: 33617 | X21: 0 | Z21: Clyra Medical Technologies, Inc. | AA21: Tampa | AC21: PCI-01 | AE21: =J21*VLOOKUP(H21,'Cost sheet'!$C$2:$G$1232,5,FALSE) -> 9291.675
A22: 46077 | B22: 46105 | C22: 2 | D22: 2 | E22: 0000065013 | F22: 2 | H22: 7862 | I22: ViaCLYR Flip Top 16oz | J22: 5000 | K22: 3.5 | L22: 17500 | M22: CLYRA | N22: Filling OP | O22: FALSE | P22: SO | R22: Clyra Medical Technologies, Inc. | S22: 10770 N 46th Street, Unit C-300 | U22: FL | V22: 33617 | X22: 0 | Z22: Clyra Medical Technologies, Inc. | AA22: Tampa | AC22: PCI-01 | AE22: =J22*VLOOKUP(H22,'Cost sheet'!$C$2:$G$1232,5,FALSE) -> 11076.47
A23: 46077 | B23: 46105 | C23: 2 | D23: 2 | E23: 0000065013 | F23: 3 | H23: 7863 | I23: ViaCLYR Flip Top 32oz | J23: 1000 | K23: 7.52 | L23: 7520 | M23: CLYRA | N23: Filling OP | O23: FALSE | P23: SO | R23: Clyra Medical Technologies, Inc. | S23: 10770 N 46th Street, Unit C-300 | U23: FL | V23: 33617 | X23: 0 | Z23: Clyra Medical Technologies, Inc. | AA23: Tampa | AC23: PCI-01 | AE23: =J23*VLOOKUP(H23,'Cost sheet'!$C$2:$G$1232,5,FALSE) -> 5463.174
A24: 46077 | B24: 46237 | C24: 2 | D24: 2 | E24: 0000065014 | F24: 1 | G24: 3440 | H24: 5045 | I24: FREUDENBERG 30cm X 47cm Nonwoven Sheets 122P0463 | J24: 25000 | K24: 1.63 | L24: 40750 | M24: FREUD | N24: MEDICAL | O24: FALSE | P24: SO | R24: Freudenberg Performance Materials LP | S24: 3440 Industrial Drive | U24: NC | V24: 27704 | X24: 0 | Z24: Freudenberg Performance Materials LP | AA24: Durham | AB24: **DO NOT DOUBLE STACK LABEL - TAKE PHOTO** | AE24: =J24*VLOOKUP(H24,'Cost sheet'!$C$2:$G$1232,5,FALSE) -> 14910
A25: 45903 | B25: 2 | C25: 46063 | D25: 46021 | E25: 0000064540 | F25: 1 | H25: 7898 | I25: MPM DryMax/DrySAP Extra Super Absorbent Drsg, Sterile, 8X8; | J25: 10000 | K25: 0.99 | L25: 9900 | M25: MPM | N25: MEDICAL | O25: FALSE | P25: SO | R25: MPM Medical, Inc. | S25: 1801 Big Town Blvd, Suite 300 | U25: TX | V25: 75149 | X25: 0 | Z25: MPM Medical, Inc. | AA25: Mesquite | AC25: PCI-01 | AE25: =J25*VLOOKUP(H25,'Cost sheet'!$C$2:$G$1232,5,FALSE) -> 9900
A26: 45987 | B26: 46104 | C26: 46073 | D26: 46086 | E26: 0000064784 | F26: 2 | G26: ICS | H26: 7153 | I26: URGO - VASHE 250 ml Flip Top 00313 | J26: 50004 | K26: 1.88 | L26: 94007.52 | M26: URGO | N26: Filling OP | O26: FALSE | P26: SO | R26: URGO Medical | S26: 167 International Blvd, Suite 550 | U26: KY | V26: 40109 | X26: 0 | Z26: ICS (Urgo Medical) | AA26: Brooks | AB26: ReceivingBrooks@icsconnect.com | AE26: =J26*VLOOKUP(H26,'Cost sheet'!$C$2:$G$1232,5,FALSE) -> 38025.842
A27: 45987 | B27: 46118 | C27: 46073 | D27: 46086 | E27: 0000064786 | F27: 1 | G27: ICS | H27: 7153 | I27: URGO - VASHE 250 ml Flip Top 00313 | J27: 45000 | K27: 1.88 | L27: 84600 | M27: URGO | N27: Filling OP | O27: FALSE | P27: SO | R27: URGO Medical | S27: 167 International Blvd, Suite 550 | U27: KY | V27: 40109 | X27: 0 | Z27: ICS (Urgo Medical) | AA27: Brooks | AB27: ReceivingBrooks@icsconnect.com | AE27: =J27*VLOOKUP(H27,'Cost sheet'!$C$2:$G$1232,5,FALSE) -> 34220.52
A28: 45987 | B28: 46125 | C28: 46073 | D28: 46086 | E28: 0000064787 | F28: 1 | G28: ICS | H28: 7153 | I28: URGO - VASHE 250 ml Flip Top 00313 | J28: 50004 | K28: 1.88 | L28: 94007.52 | M28: URGO | N28: Filling OP | O28: FALSE | P28: SO | R28: URGO Medical | S28: 167 International Blvd, Suite 550 | U28: KY | V28: 40109 | X28: 0 | Z28: ICS (Urgo Medical) | AA28: Brooks | AB28: ReceivingBrooks@icsconnect.com | AE28: =J28*VLOOKUP(H28,'Cost sheet'!$C$2:$G$1232,5,FALSE) -> 38025.842
A29: 45974 | B29: 45996 | C29: 46076 | D29: 46064 | E29: 0000064757 | F29: 1 | G29: LAND | H29: 6370 | I29: TB DRY MOUTH TINGLING RINSE 16 OZ BULK 40101908 | J29: 17475 | K29: 1.7789 | L29: 31086.28 | M29: ORORA | N29: Filling OP | O29: FALSE | P29: SO | R29: Orora Business Service Center | S29: 13397 Marlay Ave Ste A | U29: CA | V29: 92337-6946 | X29: 0 | Z29: Landsberg-Fullfillment Solutions | AA29: Fontana | AB29: Need special certificate COA before shipped | AC29: PCI-01 | AE29: =J29*VLOOKUP(H29,'Cost sheet'!$C$2:$G$1232,5,FALSE) -> 11457.361
A30: 45987 | B30: 46097 | C30: 46077 | D30: 46090 | E30: 0000064788 | F30: 1 | G30: ICS | H30: 7154 | I30: URGO - VASHE 475 ml Flip Top 00314 | J30: 30000 | K30: 2.59 | L30: 77700 | M30: URGO | N30: Filling OP | O30: FALSE | P30: SO | R30: URGO Medical | S30: 167 International Blvd, Suite 550 | U30: KY | V30: 40109 | X30: 0 | Z30: ICS (Urgo Medical) | AA30: Brooks | AB30: ReceivingBrooks@icsconnect.com | AE30: =J30*VLOOKUP(H30,'Cost sheet'!$C$2:$G$1232,5,FALSE) -> 36058.83
A31: 45594 | B31: 45685 | C31: 46078 | D31: 45709 | E31: 0000063455 | F31: 30 | G31: C02 | H31: 6011 | I31: MEDLINE CURAD MEDISTRIP 1/4 X 4 IN STERILE NON250414 | J31: 182 | K31: 127.14 | L31: 23139.48 | M31: MEDL | N31: MEDICAL | O31: FALSE | P31: SO | R31: Medline Industries, Inc. | S31: 2200 Cornerstone Pkwy, Ste 100 | U31: IL | V31: 60030 | X31: 0 | Z31: Medline Industries LP | AA31: Grayslake | AC31: PCI-01 | AE31: =J31*VLOOKUP(H31,'Cost sheet'!$C$2:$G$1232,5,FALSE) -> 10556.159
A32: 45618 | B32: 45709 | C32: 46078 | D32: 45709 | E32: 0000063558 | F32: 10 | G32: B25 | H32: 6011 | I32: MEDLINE CURAD MEDISTRIP 1/4 X 4 IN STERILE NON250414 | J32: 26 | K32: 127.14 | L32: 3305.64 | M32: MEDL | N32: MEDICAL | O32: FALSE | P32: SO | R32: Medline Industries, Inc. | S32: 1401 N. Universal Ave. | U32: MO | V32: 641202139 | X32: 0 | Z32: Medline Industries LP | AA32: KANSAS CITY | AC32: PCI-01 | AE32: =J32*VLOOKUP(H32,'Cost sheet'!$C$2:$G$1232,5,FALSE) -> 1508.0226
A33: 45618 | B33: 45709 | C33: 46078 | D33: 45709 | E33: 0000063559 | F33: 30 | G33: C57 | H33: 6011 | I33: MEDLINE CURAD MEDISTRIP 1/4 X 4 IN STERILE NON250414 | J33: 8 | K33: 127.14 | L33: 1017.12 | M33: MEDL | N33: MEDICAL | O33: FALSE | P33: SO | R33: Medline Industries, Inc. | S33: 5511 West Ten Rd | U33: NC | V33: 27302 | X33: 0 | Z33: Medline Industries LP | AA33: Mebane | AC33: PCI-01 | AE33: =J33*VLOOKUP(H33,'Cost sheet'!$C$2:$G$1232,5,FALSE) -> 464.00697
A34: 45636 | B34: 45726 | C34: 46078 | D34: 45761 | E34: 0000063612 | F34: 60 | G34: C09 | H34: 6011 | I34: MEDLINE CURAD MEDISTRIP 1/4 X 4 IN STERILE NON250414 | J34: 104 | K34: 127.14 | L34: 13222.56 | M34: MEDL | N34: MEDICAL | O34: FALSE | P34: SO | R34: Medline Industries, Inc. | S34: 1960 W Miro Way | U34: CA | V34: 92376 | X34: 0 | Z34: Medline Industries LP | AA34: Rialto | AC34: PCI-01 | AE34: =J34*VLOOKUP(H34,'Cost sheet'!$C$2:$G$1232,5,FALSE) -> 6032.0906
A35: 45706 | B35: 45790 | C35: 46078 | D35: 45919 | E35: 0000063836 | F35: 10 | G35: C47 | H35: 6013 | I35: MEDLINE CURAD MEDI STRIP 1 X 5 NON250501 | J35: 3 | K35: 123 | L35: 369 | M35: MEDL | N35: MEDICAL | O35: FALSE | P35: SO | R35: Medline Industries, Inc. | S35: 239 Belvidere Rd | U35: MD | V35: 21903 | X35: 0 | Z35: Medline Industries LP | AA35: Perryville | AC35: PCI-01 | AE35: =J35*VLOOKUP(H35,'Cost sheet'!$C$2:$G$1232,5,FALSE) -> 180.1643
A36: 45706 | B36: 45790 | C36: 46078 | D36: 45919 | E36: 0000063843 | F36: 20 | G36: B11 | H36: 6013 | I36: MEDLINE CURAD MEDI STRIP 1 X 5 NON250501 | J36: 1 | K36: 123 | L36: 123 | M36: MEDL | N36: MEDICAL | O36: FALSE | P36: SO | R36: Medline Industries, Inc. | S36: 21111 E. 36th Drive | U36: CO | V36: 80011 | X36: 0 | Z36: Medline Industries LP | AA36: Aurora | AC36: PCI-01 | AE36: =J36*VLOOKUP(H36,'Cost sheet'!$C$2:$G$1232,5,FALSE) -> 60.054767
A37: 45706 | B37: 45790 | C37: 46078 | D37: 45919 | E37: 0000063854 | F37: 20 | G37: C02 | H37: 6013 | I37: MEDLINE CURAD MEDI STRIP 1 X 5 NON250501 | J37: 5 | K37: 123 | L37: 615 | M37: MEDL | N37: MEDICAL | O37: FALSE | P37: SO | R37: Medline Industries, Inc. | S37: 2200 Cornerstone Pkwy, Ste 100 | U37: IL | V37: 60030 | X37: 0 | Z37: Medline Industries LP | AA37: Grayslake | AC37: PCI-01 | AE37: =J37*VLOOKUP(H37,'Cost sheet'!$C$2:$G$1232,5,FALSE) -> 300.27383
A38: 45706 | B38: 45790 | C38: 46078 | D38: 45919 | E38: 0000063855 | F38: 10 | G38: B01 | H38: 6013 | I38: MEDLINE CURAD MEDI STRIP 1 X 5 NON250501 | J38: 37 | K38: 123 | L38: 4551 | M38: MEDL | N38: MEDICAL | O38: FALSE | P38: SO | R38: Medline Industries, Inc. | S38: 1200 Townline Rd. | U38: IL | V38: 60060 | X38: 0 | Z38: Medline Industries LP | AA38: Mundelein | AC38: PCI-01 | AE38: =J38*VLOOKUP(H38,'Cost sheet'!$C$2:$G$1232,5,FALSE) -> 2222.0264
A39: 45720 | B39: 45805 | C39: 46078 | D39: 45919 | E39: 0000063882 | F39: 20 | G39: C40 | H39: 6013 | I39: MEDLINE CURAD MEDI STRIP 1 X 5 NON250501 | J39: 5 | K39: 123 | L39: 615 | M39: MEDL | N39: MEDICAL | O39: FALSE | P39: SO | R39: Medline Industries, Inc. | S39: 81 Campanelli Drive | U39: MA | V39: 01569 | X39: 0 | Z39: Medline Industries LP | AA39: UXBRIDGE | AC39: PCI-01 | AE39: =J39*VLOOKUP(H39,'Cost sheet'!$C$2:$G$1232,5,FALSE) -> 300.27383
A40: 45720 | B40: 45805 | C40: 46078 | D40: 45919 | E40: 0000063883 | F40: 30 | G40: B06 | H40: 6013 | I40: MEDLINE CURAD MEDI STRIP 1 X 5 NON250501 | J40: 9 | K40: 123 | L40: 1107 | M40: MEDL | N40: MEDICAL | O40: FALSE | P40: SO | R40: Medline Industries, Inc. | S40: 1 Medline Drive, Suite 100 | U40: TX | V40: 75172 | X40: 0 | Z40: Medline Industries LP | AA40: Wilmer | AC40: PCI-01 | AE40: =J40*VLOOKUP(H40,'Cost sheet'!$C$2:$G$1232,5,FALSE) -> 540.4929
A41: 45720 | B41: 45805 | C41: 46078 | D41: 45919 | E41: 0000063885 | F41: 10 | G41: B11 | H41: 6013 | I41: MEDLINE CURAD MEDI STRIP 1 X 5 NON250501 | J41: 3 | K41: 123 | L41: 369 | M41: MEDL | N41: MEDICAL | O41: FALSE | P41: SO | R41: Medline Industries, Inc. | S41: 21111 E. 36th Drive | U41: CO | V41: 80011 | X41: 0 | Z41: Medline Industries LP | AA41: Aurora | AC41: PCI-01 | AE41: =J41*VLOOKUP(H41,'Cost sheet'!$C$2:$G$1232,5,FALSE) -> 180.1643
...

Sheet Detail3
A1: Details for Sum of ExtendedLineAmount - Months (ScheduledShipDate): Dec, Years (ScheduledShipDate): 2026, ItemSalesClassCode: Filling OP, ItemCode: N-4001 (+)
A3: ScheduledShipDate | B3: PromisedShipDate | C3: SONumber | D3: LineNumber | E3: ShipToCode | F3: ItemCode | G3: ItemDescription | H3: OrderQuantity | I3: UnitPrice | J3: ExtendedLineAmount | K3: CustomerCode | L3: ItemSalesClassCode | M3: DropShip | N3: SOTypeCode | O3: FinalDestination | P3: CustomerName | Q3: ShipToAddress1 | R3: ShipToAddress2 | S3: ShipToStateCode | T3: ShipToZip | U3: ParentDocumentNumber | V3: Weight | W3: OrderMessage | X3: ShipToName | Y3: ShipToCity | Z3: ShippingInstructions | AA3: WarehouseCode | AB3: WarehouseName
A4: 46387 | B4: 46031 | C4: 0000064678 | D4: 10 | E4: C54 | F4: 4357 | G4: CURAD MEDIPLAST WART REMOVER CUR01496 | H4: 112 | I4: 57.96 | J4: 6491.52 | K4: MEDL | L4: MEDICAL | M4: FALSE | N4: SO | P4: Medline Industries, Inc. | Q4: 494 State Route 416 | R4: 494 State Route 416 | S4: NY | T4: 12549 | V4: 0 | X4: Medline Industries LP | Y4: Montgomery | AA4: PCI-01 | AB4: STRUKMYER, LLC
A5: 46387 | B5: 46031 | C5: 0000064676 | D5: 10 | E5: K46 | F5: 4357 | G5: CURAD MEDIPLAST WART REMOVER CUR01496 | H5: 14 | I5: 57.96 | J5: 811.44 | K5: MEDL | L5: MEDICAL | M5: FALSE | N5: SO | P5: Medline Industries, Inc. | Q5: 18601 Christopher Way, STE 100 | R5: 18601 Christopher Way, STE 100 | S5: CA | T5: 95330 | V5: 0 | X5: Medline Industries, Inc. | Y5: Lathrop | AA5: PCI-01 | AB5: STRUKMYER, LLC
A6: 46387 | B6: 46031 | C6: 0000064675 | D6: 10 | E6: C42 | F6: 4357 | G6: CURAD MEDIPLAST WART REMOVER CUR01496 | H6: 70 | I6: 57.96 | J6: 4057.2 | K6: MEDL | L6: MEDICAL | M6: FALSE | N6: SO | P6: Medline Industries, Inc. | Q6: 3446 Highway 51 N, Suite 100 | S6: MS | T6: 38672 | V6: 0 | X6: Medline Industries LP | Y6: Southaven | AA6: PCI-01 | AB6: STRUKMYER, LLC
A7: 46387 | B7: 46031 | C7: 0000064674 | D7: 10 | E7: C09 | F7: 4357 | G7: CURAD MEDIPLAST WART REMOVER CUR01496 | H7: 56 | I7: 57.96 | J7: 3245.76 | K7: MEDL | L7: MEDICAL | M7: FALSE | N7: SO | P7: Medline Industries, Inc. | Q7: 1960 W Miro Way | S7: CA | T7: 92376 | V7: 0 | X7: Medline Industries LP | Y7: Rialto | AA7: PCI-01 | AB7: STRUKMYER, LLC
A8: 46387 | B8: 46031 | C8: 0000064673 | D8: 10 | E8: B06 | F8: 4357 | G8: CURAD MEDIPLAST WART REMOVER CUR01496 | H8: 84 | I8: 57.96 | J8: 4868.64 | K8: MEDL | L8: MEDICAL | M8: FALSE | N8: SO | P8: Medline Industries, Inc. | Q8: 1 Medline Drive, Suite 100 | S8: TX | T8: 75172 | V8: 0 | X8: Medline Industries LP | Y8: Wilmer | AA8: PCI-01 | AB8: STRUKMYER, LLC
A9: 46387 | B9: 46031 | C9: 0000064672 | D9: 10 | E9: K56 | F9: 4357 | G9: CURAD MEDIPLAST WART REMOVER CUR01496 | H9: 14 | I9: 57.96 | J9: 811.44 | K9: MEDL | L9: MEDICAL | M9: FALSE | N9: SO | P9: Medline Industries, Inc. | Q9: 190 Medline Drive Suite 200 | S9: GA | T9: 31324 | V9: 0 | X9: Medline Industries LP | Y9: Richmond Hill | AA9: PCI-01 | AB9: STRUKMYER, LLC
A10: 46387 | B10: 46031 | C10: 0000064670 | D10: 10 | E10: C05 | F10: 4357 | G10: CURAD MEDIPLAST WART REMOVER CUR01496 | H10: 28 | I10: 57.96 | J10: 1622.88 | K10: MEDL | L10: MEDICAL | M10: FALSE | N10: SO | P10: Medline Industries, Inc. | Q10: 1062 Old Dixie Hwy | S10: FL | T10: 33823 | V10: 0 | X10: Medline Industries LP | Y10: Auburndale | AA10: PCI-01 | AB10: STRUKMYER, LLC
A11: 46387 | B11: 46031 | C11: 0000064669 | D11: 10 | E11: C03 | F11: 4357 | G11: CURAD MEDIPLAST WART REMOVER CUR01496 | H11: 140 | I11: 57.96 | J11: 8114.4 | K11: MEDL | L11: MEDICAL | M11: FALSE | N11: SO | P11: Medline Industries, Inc. | Q11: 1500 Medline Place | S11: GA | T11: 30253 | V11: 0 | X11: Medline Industries LP | Y11: McDonough | AA11: PCI-01 | AB11: STRUKMYER, LLC
A12: 46387 | B12: 46031 | C12: 0000064667 | D12: 10 | E12: C47 | F12: 4357 | G12: CURAD MEDIPLAST WART REMOVER CUR01496 | H12: 28 | I12: 57.96 | J12: 1622.88 | K12: MEDL | L12: MEDICAL | M12: FALSE | N12: SO | P12: Medline Industries, Inc. | Q12: 239 Belvidere Rd | S12: MD | T12: 21903 | V12: 0 | X12: Medline Industries LP | Y12: Perryville | AA12: PCI-01 | AB12: STRUKMYER, LLC
A13: 46387 | B13: 46017 | C13: 0000064643 | D13: 10 | E13: B24 | F13: 4357 | G13: CURAD MEDIPLAST WART REMOVER CUR01496 | H13: 28 | I13: 57.96 | J13: 1622.88 | K13: MEDL | L13: MEDICAL | M13: FALSE | N13: SO | P13: Medline Industries, Inc. | Q13: 8001 SW 47th St. | S13: OK | T13: 73179 | V13: 0 | X13: Medline Industries LP | Y13: Oklahoma City | AA13: PCI-01 | AB13: STRUKMYER, LLC
A14: 46387 | B14: 46017 | C14: 0000064642 | D14: 10 | E14: C05 | F14: 4357 | G14: CURAD MEDIPLAST WART REMOVER CUR01496 | H14: 14 | I14: 57.96 | J14: 811.44 | K14: MEDL | L14: MEDICAL | M14: FALSE | N14: SO | P14: Medline Industries, Inc. | Q14: 1062 Old Dixie Hwy | S14: FL | T14: 33823 | V14: 0 | X14: Medline Industries LP | Y14: Auburndale | AA14: PCI-01 | AB14: STRUKMYER, LLC
A15: 46387 | B15: 46017 | C15: 0000064641 | D15: 10 | E15: C02 | F15: 4357 | G15: CURAD MEDIPLAST WART REMOVER CUR01496 | H15: 182 | I15: 57.96 | J15: 10548.72 | K15: MEDL | L15: MEDICAL | M15: FALSE | N15: SO | P15: Medline Industries, Inc. | Q15: 2200 Cornerstone Pkwy, Ste 100 | S15: IL | T15: 60030 | V15: 0 | X15: Medline Industries LP | Y15: Grayslake | AA15: PCI-01 | AB15: STRUKMYER, LLC
A16: 46387 | B16: 46020 | C16: 0000064639 | D16: 10 | E16: C03 | F16: 4357 | G16: CURAD MEDIPLAST WART REMOVER CUR01496 | H16: 14 | I16: 57.96 | J16: 811.44 | K16: MEDL | L16: MEDICAL | M16: FALSE | N16: SO | P16: Medline Industries, Inc. | Q16: 1500 Medline Place | S16: GA | T16: 30253 | V16: 0 | X16: Medline Industries LP | Y16: McDonough | AA16: PCI-01 | AB16: STRUKMYER, LLC
A17: 46387 | B17: 46017 | C17: 0000064636 | D17: 10 | E17: C47 | F17: 4357 | G17: CURAD MEDIPLAST WART REMOVER CUR01496 | H17: 14 | I17: 57.96 | J17: 811.44 | K17: MEDL | L17: MEDICAL | M17: FALSE | N17: SO | P17: Medline Industries, Inc. | Q17: 239 Belvidere Rd | S17: MD | T17: 21903 | V17: 0 | X17: Medline Industries LP | Y17: Perryville | AA17: PCI-01 | AB17: STRUKMYER, LLC
A18: 46387 | B18: 46017 | C18: 0000064635 | D18: 10 | E18: C54 | F18: 4357 | G18: CURAD MEDIPLAST WART REMOVER CUR01496 | H18: 28 | I18: 57.96 | J18: 1622.88 | K18: MEDL | L18: MEDICAL | M18: FALSE | N18: SO | P18: Medline Industries, Inc. | Q18: 494 State Route 416 | R18: 494 State Route 416 | S18: NY | T18: 12549 | V18: 0 | X18: Medline Industries LP | Y18: Montgomery | AA18: PCI-01 | AB18: STRUKMYER, LLC
A19: 46387 | B19: 46020 | C19: 0000064633 | D19: 10 | E19: C42 | F19: 4357 | G19: CURAD MEDIPLAST WART REMOVER CUR01496 | H19: 28 | I19: 57.96 | J19: 1622.88 | K19: MEDL | L19: MEDICAL | M19: FALSE | N19: SO | P19: Medline Industries, Inc. | Q19: 3446 Highway 51 N, Suite 100 | S19: MS | T19: 38672 | V19: 0 | X19: Medline Industries LP | Y19: Southaven | AA19: PCI-01 | AB19: STRUKMYER, LLC
A20: 46387 | B20: 46020 | C20: 0000064632 | D20: 10 | E20: C02 | F20: 4357 | G20: CURAD MEDIPLAST WART REMOVER CUR01496 | H20: 182 | I20: 57.96 | J20: 10548.72 | K20: MEDL | L20: MEDICAL | M20: FALSE | N20: SO | P20: Medline Industries, Inc. | Q20: 2200 Cornerstone Pkwy, Ste 100 | S20: IL | T20: 60030 | V20: 0 | X20: Medline Industries LP | Y20: Grayslake | AA20: PCI-01 | AB20: STRUKMYER, LLC
A21: 46387 | B21: 46020 | C21: 0000064631 | D21: 10 | E21: K46 | F21: 4357 | G21: CURAD MEDIPLAST WART REMOVER CUR01496 | H21: 14 | I21: 57.96 | J21: 811.44 | K21: MEDL | L21: MEDICAL | M21: FALSE | N21: SO | P21: Medline Industries, Inc. | Q21: 18601 Christopher Way, STE 100 | R21: 18601 Christopher Way, STE 100 | S21: CA | T21: 95330 | V21: 0 | X21: Medline Industries, Inc. | Y21: Lathrop | AA21: PCI-01 | AB21: STRUKMYER, LLC
A22: 46387 | B22: 46017 | C22: 0000064630 | D22: 10 | E22: C41 | F22: 4357 | G22: CURAD MEDIPLAST WART REMOVER CUR01496 | H22: 14 | I22: 57.96 | J22: 811.44 | K22: MEDL | L22: MEDICAL | M22: FALSE | N22: SO | P22: Medline Industries, Inc. | Q22: 1040 Enterprise Parkway | S22: OH | T22: 43162 | V22: 0 | X22: Medline Industries LP | Y22: West Jefferson | AA22: PCI-01 | AB22: STRUKMYER, LLC
A23: 46387 | B23: 46020 | C23: 0000064629 | D23: 10 | E23: C09 | F23: 4357 | G23: CURAD MEDIPLAST WART REMOVER CUR01496 | H23: 28 | I23: 57.96 | J23: 1622.88 | K23: MEDL | L23: MEDICAL | M23: FALSE | N23: SO | P23: Medline Industries, Inc. | Q23: 1960 W Miro Way | S23: CA | T23: 92376 | V23: 0 | X23: Medline Industries LP | Y23: Rialto | AA23: PCI-01 | AB23: STRUKMYER, LLC
A24: 46387 | B24: 46020 | C24: 0000064628 | D24: 10 | E24: C05 | F24: 4357 | G24: CURAD MEDIPLAST WART REMOVER CUR01496 | H24: 42 | I24: 57.96 | J24: 2434.32 | K24: MEDL | L24: MEDICAL | M24: FALSE | N24: SO | P24: Medline Industries, Inc. | Q24: 1062 Old Dixie Hwy | S24: FL | T24: 33823 | V24: 0 | X24: Medline Industries LP | Y24: Auburndale | AA24: PCI-01 | AB24: STRUKMYER, LLC
A25: 46387 | B25: 46017 | C25: 0000064627 | D25: 10 | E25: C89 | F25: 4357 | G25: CURAD MEDIPLAST WART REMOVER CUR01496 | H25: 182 | I25: 57.96 | J25: 10548.72 | K25: MEDL | L25: MEDICAL | M25: FALSE | N25: SO | P25: Medline Industries, Inc. | Q25: 251 Hilton Dr | S25: IN | T25: 47130 | V25: 0 | X25: Medline Industries LP | Y25: Jeffersonville | AA25: PCI-01 | AB25: STRUKMYER, LLC
A26: 46387 | B26: 46020 | C26: 0000064626 | D26: 10 | E26: B29 | F26: 4357 | G26: CURAD MEDIPLAST WART REMOVER CUR01496 | H26: 28 | I26: 57.96 | J26: 1622.88 | K26: MEDL | L26: MEDICAL | M26: FALSE | N26: SO | P26: Medline Industries, Inc. | Q26: 13115 Brockton Lane N | S26: MN | T26: 55374 | V26: 0 | X26: Medline Industries LP | Y26: Rogers | AA26: PCI-01 | AB26: STRUKMYER, LLC
A27: 46387 | B27: 46017 | C27: 0000064625 | D27: 10 | E27: C09 | F27: 4357 | G27: CURAD MEDIPLAST WART REMOVER CUR01496 | H27: 56 | I27: 57.96 | J27: 3245.76 | K27: MEDL | L27: MEDICAL | M27: FALSE | N27: SO | P27: Medline Industries, Inc. | Q27: 1960 W Miro Way | S27: CA | T27: 92376 | V27: 0 | X27: Medline Industries LP | Y27: Rialto | AA27: PCI-01 | AB27: STRUKMYER, LLC
A28: 46387 | B28: 46002 | C28: 0000064573 | D28: 10 | E28: C02 | F28: 4357 | G28: CURAD MEDIPLAST WART REMOVER CUR01496 | H28: 98 | I28: 57.96 | J28: 5680.08 | K28: MEDL | L28: MEDICAL | M28: FALSE | N28: SO | P28: Medline Industries, Inc. | Q28: 2200 Cornerstone Pkwy, Ste 100 | S28: IL | T28: 60030 | V28: 0 | X28: Medline Industries LP | Y28: Grayslake | AA28: PCI-01 | AB28: STRUKMYER, LLC
A29: 46387 | B29: 46002 | C29: 0000064572 | D29: 10 | E29: C03 | F29: 4357 | G29: CURAD MEDIPLAST WART REMOVER CUR01496 | H29: 28 | I29: 57.96 | J29: 1622.88 | K29: MEDL | L29: MEDICAL | M29: FALSE | N29: SO | P29: Medline Industries, Inc. | Q29: 1500 Medline Place | S29: GA | T29: 30253 | V29: 0 | X29: Medline Industries LP | Y29: McDonough | AA29: PCI-01 | AB29: STRUKMYER, LLC
A30: 46387 | B30: 46002 | C30: 0000064570 | D30: 10 | E30: K56 | F30: 4357 | G30: CURAD MEDIPLAST WART REMOVER CUR01496 | H30: 14 | I30: 57.96 | J30: 811.44 | K30: MEDL | L30: MEDICAL | M30: FALSE | N30: SO | P30: Medline Industries, Inc. | Q30: 190 Medline Drive Suite 200 | S30: GA | T30: 31324 | V30: 0 | X30: Medline Industries LP | Y30: Richmond Hill | AA30: PCI-01 | AB30: STRUKMYER, LLC
A31: 46387 | B31: 46002 | C31: 0000064567 | D31: 10 | E31: C42 | F31: 4357 | G31: CURAD MEDIPLAST WART REMOVER CUR01496 | H31: 126 | I31: 57.96 | J31: 7302.96 | K31: MEDL | L31: MEDICAL | M31: FALSE | N31: SO | P31: Medline Industries, Inc. | Q31: 3446 Highway 51 N, Suite 100 | S31: MS | T31: 38672 | V31: 0 | X31: Medline Industries LP | Y31: Southaven | AA31: PCI-01 | AB31: STRUKMYER, LLC
A32: 46387 | B32: 46002 | C32: 0000064565 | D32: 10 | E32: C54 | F32: 4357 | G32: CURAD MEDIPLAST WART REMOVER CUR01496 | H32: 112 | I32: 57.96 | J32: 6491.52 | K32: MEDL | L32: MEDICAL | M32: FALSE | N32: SO | P32: Medline Industries, Inc. | Q32: 494 State Route 416 | R32: 494 State Route 416 | S32: NY | T32: 12549 | V32: 0 | X32: Medline Industries LP | Y32: Montgomery | AA32: PCI-01 | AB32: STRUKMYER, LLC
A33: 46387 | B33: 45989 | C33: 0000064539 | D33: 10 | E33: C47 | F33: 4357 | G33: CURAD MEDIPLAST WART REMOVER CUR01496 | H33: 42 | I33: 57.96 | J33: 2434.32 | K33: MEDL | L33: MEDICAL | M33: FALSE | N33: SO | P33: Medline Industries, Inc. | Q33: 239 Belvidere Rd | S33: MD | T33: 21903 | V33: 0 | X33: Medline Industries LP | Y33: Perryville | AA33: PCI-01 | AB33: STRUKMYER, LLC
A34: 46387 | B34: 45989 | C34: 0000064538 | D34: 10 | E34: C75 | F34: 4357 | G34: CURAD MEDIPLAST WART REMOVER CUR01496 | H34: 14 | I34: 57.96 | J34: 811.44 | K34: MEDL | L34: MEDICAL | M34: FALSE | N34: SO | P34: Medline Industries, Inc. | Q34: 3770 Hogum Bay Road Ne | S34: WA | T34: 98516 | V34: 0 | X34: Medline Industries LP | Y34: Lacey | AA34: PCI-01 | AB34: STRUKMYER, LLC
A35: 46387 | B35: 45989 | C35: 0000064536 | D35: 10 | E35: C42 | F35: 4357 | G35: CURAD MEDIPLAST WART REMOVER CUR01496 | H35: 28 | I35: 57.96 | J35: 1622.88 | K35: MEDL | L35: MEDICAL | M35: FALSE | N35: SO | P35: Medline Industries, Inc. | Q35: 3446 Highway 51 N, Suite 100 | S35: MS | T35: 38672 | V35: 0 | X35: Medline Industries LP | Y35: Southaven | AA35: PCI-01 | AB35: STRUKMYER, LLC
A36: 46387 | B36: 45989 | C36: 0000064535 | D36: 10 | E36: C41 | F36: 4357 | G36: CURAD MEDIPLAST WART REMOVER CUR01496 | H36: 14 | I36: 57.96 | J36: 811.44 | K36: MEDL | L36: MEDICAL | M36: FALSE | N36: SO | P36: Medline Industries, Inc. | Q36: 1040 Enterprise Parkway | S36: OH | T36: 43162 | V36: 0 | X36: Medline Industries LP | Y36: West Jefferson | AA36: PCI-01 | AB36: STRUKMYER, LLC
A37: 46387 | B37: 45989 | C37: 0000064534 | D37: 10 | E37: K46 | F37: 4357 | G37: CURAD MEDIPLAST WART REMOVER CUR01496 | H37: 14 | I37: 57.96 | J37: 811.44 | K37: MEDL | L37: MEDICAL | M37: FALSE | N37: SO | P37: Medline Industries, Inc. | Q37: 18601 Christopher Way, STE 100 | R37: 18601 Christopher Way, STE 100 | S37: CA | T37: 95330 | V37: 0 | X37: Medline Industries, Inc. | Y37: Lathrop | AA37: PCI-01 | AB37: STRUKMYER, LLC
A38: 46387 | B38: 45989 | C38: 0000064533 | D38: 10 | E38: C54 | F38: 4357 | G38: CURAD MEDIPLAST WART REMOVER CUR01496 | H38: 210 | I38: 57.96 | J38: 12171.6 | K38: MEDL | L38: MEDICAL | M38: FALSE | N38: SO | P38: Medline Industries, Inc. | Q38: 494 State Route 416 | R38: 494 State Route 416 | S38: NY | T38: 12549 | V38: 0 | X38: Medline Industries LP | Y38: Montgomery | AA38: PCI-01 | AB38: STRUKMYER, LLC
A39: 46387 | B39: 45989 | C39: 0000064532 | D39: 10 | E39: C40 | F39: 4357 | G39: CURAD MEDIPLAST WART REMOVER CUR01496 | H39: 28 | I39: 57.96 | J39: 1622.88 | K39: MEDL | L39: MEDICAL | M39: FALSE | N39: SO | P39: Medline Industries, Inc. | Q39: 81 Campanelli Drive | S39: MA | T39: 01569 | V39: 0 | X39: Medline Industries LP | Y39: UXBRIDGE | AA39: PCI-01 | AB39: STRUKMYER, LLC
A40: 46387 | B40: 45989 | C40: 0000064531 | D40: 10 | E40: B30 | F40: 4357 | G40: CURAD MEDIPLAST WART REMOVER CUR01496 | H40: 14 | I40: 57.96 | J40: 811.44 | K40: MEDL | L40: MEDICAL | M40: FALSE | N40: SO | P40: Medline Industries, Inc. | Q40: 1900 Meadowville Technology Parkway | S40: VA | T40: 23836 | V40: 0 | X40: Medline Industries LP | Y40: Chester | AA40: PCI-01 | AB40: STRUKMYER, LLC
A41: 46387 | B41: 45989 | C41: 0000064527 | D41: 10 | E41: C09 | F41: 4357 | G41: CURAD MEDIPLAST WART REMOVER CUR01496 | H41: 294 | I41: 57.96 | J41: 17040.24 | K41: MEDL | L41: MEDICAL | M41: FALSE | N41: SO | P41: Medline Industries, Inc. | Q41: 1960 W Miro Way | S41: CA | T41: 92376 | V41: 0 | X41: Medline Industries LP | Y41: Rialto | AA41: PCI-01 | AB41: STRUKMYER, LLC
...

Sheet Sales Map per month
C1: TOTAL SALES
C2: =D23 -> 9065728.6 | H2: N Codes
A3: ItemSalesClassCode | B3: (All) | G3: ItemCode | H3: (Multiple Items)
A4: ItemCode | B4: (All) | G4: ItemSalesClassCode | H4: (All)
A6: Sum of ExtendedLineAmount | G6: N Code Sales
A7: Years (ScheduledShipDate) | B7: Months (ScheduledShipDate) | C7: ScheduledShipDate | D7: Total | G7: ScheduledShipDate | H7: Total
A8: 1900 | B8: Jan | D8: 465850.23 | G8: 2 | H8: 17822
A9: 1900 Total | D9: 465850.23 | G9: 46296 | H9: 13339.02
A10: 2026 | B10: Feb | D10: 1189209.4 | G10: 46080 | H10: 4755.79
B11: Mar | D11: 2106445.2 | G11: 46113 | H11: 54691
B12: Apr | D12: 1598583.1 | G12: 46142 | H12: 250
B13: May | D13: 1038408.3 | G13: 46094 | H13: 6700
B14: Jun | D14: 230497 | G14: Grand Total | H14: 97557.81
B15: Jul | D15: 376891
B16: Aug | D16: 253135.5
B17: Sep | D17: 129838
B18: Oct | D18: 225388.52
B19: Nov | D19: 300112.02
B20: Dec | D20: 1092927.4
A21: 2026 Total | D21: 8541435.4
A22: 2027 | D22: 58443
A23: Grand Total | D23: 9065728.6

Sheet Sales by Product
A1: ItemSalesClassCode | B1: (All) | C1: =GETPIVOTDATA("Sum of ExtendedLineAmount",$A$6) -> 1189209.4
A2: ScheduledShipDate | B2: (All)
A3: Months (ScheduledShipDate) | B3: Feb | C3: =C8 -> 272615.04 | D3: Items at risk
A4: Years (ScheduledShipDate) | B4: 2026
C6: Data
A7: ItemCode | B7: ItemDescription | C7: Sum of ExtendedLineAmount | D7: Sum of OrderQuantity
A8: 7153 | B8: URGO - VASHE 250 ml Flip Top 00313 | C8: 272615.04 | D8: 145008
A9: 7156 | B9: URGO - VASHE 475 ml Instill 00317 | C9: 154960.32 | D9: 30504
A10: 1674 | B10: BI OVERLAY #2 - ITALY | C10: 118500 | D10: 500000
A11: 7487 | B11: CARDINAL HEALTH TELFA ADHESIVE DRESSING 2"x3" 6017 | C11: 80928 | D11: 300
A12: 7154 | B12: URGO - VASHE 475 ml Flip Top 00314 | C12: 77700 | D12: 30000
A13: 7235 | B13: HARMAC PRTD DRAPE ASSEMBLY P3113231 REV.A (ROW) | C13: 62532 | D13: 120000
A14: 3958 | B14: Harmac Filter Disc P3113306 Rev E | C14: 54675 | D14: 202500
A15: 5342 | B15: ISI LARGE ALUMI-HAND 760 | C15: 53130 | D15: 6900
A16: 6011 | B16: MEDLINE CURAD MEDISTRIP 1/4 X 4 IN STERILE NON250414 | C16: 43227.6 | D16: 340
A17: 5045 | B17: FREUDENBERG 30cm X 47cm Nonwoven Sheets 122P0463 | C17: 40750 | D17: 25000
A18: 6370 | B18: TB DRY MOUTH TINGLING RINSE 16 OZ BULK 40101908 | C18: 31086.28 | D18: 17475
A19: 6013 | B19: MEDLINE CURAD MEDI STRIP 1 X 5 NON250501 | C19: 26199 | D19: 213
... A27: 5660 | B27: MPM Antiseptic Wound & Skin Cleanser 8 fl.oz. MP00032 | C27: 8758.2 | D27: 3981
A28: F-22007 | B28: ADVANCED 2" × 200' ROLL SEMI-OCCLUSIVE | C28: 8599.2 | D28: 40
A29: 5520 | B29: D* Tetrapotassium Pyrophosphate CAS#7320-34-5 1614086 | C29: 8331.11 | D29: 7446
A30: 6328 | B30: CARBOX WAX SENTRY POLYETHYLENE GLYCOL 600 NF CAS#25322-68-3 | C30: 6977.1 | D30: 716188
A31: F-22004 | B31: 5 SITE SEMI-OCCLUSIVE STRIP | C31: 6560 | D31: 16000
A32: 6323 | B32: MINERALIZ GU/Zn CAS# 4468-02-4 KOSHER | C32: 4961.39 | D32: 66959
A33: F-22008 | B33: ADVANCED 2" × 200' ROLL OCCLUSIVE | C33: 4134.4 | D33: 40
A34: 5521 | B34: D* Tetrasodium Pyrophosphate CAS#7722-88-5 KOSHER | C34: 3825.84 | D34: 13337
A35: N-4008 | B35: Expedite Fee for 15ml Bottles | C35: 2556.79 | D35: 1
A36: 5515 | B36: D* Dentsil DS 60 HYDRATED SILICA - CAS#112926-00-8 KOSHER | C36: 2414.7 | D36: 467602
A37: 5590 | B37: BAG, AP2390.11 Arena "Air-Evac" Vertex, 3Ply Liquid Liner Bag | C37: 1863.13 | D37: 14
A38: 5703 | B38: D* Glycerin 99.7% CAS# 56-81-5 KOSHER | C38: 1661.22 | D38: 2013600
A39: 5639 | B39: D* Sorbitol Crystalline Powder NF, CAS# 50-70-4 KOSHER | C39: 1215.81 | D39: 214127.05
A40: N-4009 | B40: Artwork Prep/Plate Fee(s) | C40: 1200 | D40: 1
A41: 5525 | B41: D* AmmoniumGlycyrrhizate Magnasweet 110-2X CAS#53956-04-0 KOSHER | C41: 1033.12 | D41: 81438
A42: N-4001 | B42: Art & Print Plate Charges | C42: 549 | D42: 1
B43: Set Up Charges | C43: 450 | D43: 1
A44: 5518 | B44: D* Mint Flavor WONF OS, Natural 113.19228 CAS# 68917-18-0 KOSHER | C44: 963.58 | D44: 16562
A45: 5713 | B45: Polysorbate 20 CAS# 9005-64-5 | C45: 919.01 | D45: 112638
A46: 6330 | B46: MENTHOL CAS#2216-51-5 KOSHER | C46: 867.7 | D46: 9524
A47: 7224 | B47: GREEN TEA PHYTOBASIC IN PG (3345L) KOSHER | C47: 853.65 | D47: 15375
A48: 5517 | B48: D* Cooling Type Flavor Natural 113.90468 KOSHER | C48: 790.04 | D48: 48563.98
...

Sheet Sales by Customer
A1: ItemCode | B1: (All) | E1: ScheduledShipDate | F1: (All)
G2: =GETPIVOTDATA("ExtendedLineAmount",$E$2) -> 9065728.6
A3: Department | B3: Total | H3: Data
A4: URGO Medical | B4: 1973775.4 | E4: CustomerName | F4: ItemCode | G4: ItemDescription | H4: Site Total Sales Revenue | I4: Sum of Profit | K4: UOM | L4: MOQ on Cost sheet | M4: Lots/yr | N4: Comment(MOQ on sales sheet) | O4: Actual MOQ required | P4: 44927 | Q4: 44958 | R4: 44986 | S4: 45017 | T4: 45047 | U4: 45078 | V4: 45108 | W4: 45139 | X4: 45170 | Y4: 45200 | Z4: 45231 | AA4: 45261
A5: Patient Recovery | B5: 1848764.4 | E5: MPM Medical, Inc. | F5: 5671 | G5: MPM OraMagic Rx 12oz MP00213 | H5: 6408 | I5: 2833.7004 | K5: EA | L5: 5000 | M5: =J5/L5 -> 0
A6: Medline Industries, Inc. | B6: 610273.92 | F6: 5674 | G6: MPM OraMagic Plus 8oz MP00224 | H6: 4900 | I6: 1261.37 | K6: EA | L6: 75000 | M6: =J6/L6 -> 0
A7: Harmac Medical Products | B7: 568917 | F7: 5668 | G7: MPM Regenecare HA Gel 3oz. MP00107 | H7: 23400 | I7: 7417.69 | K7: EA | L7: 7000 | M7: =J7/L7 -> 0
A8: Instrument Specialists Inc | B8: 471827 | F8: 5660 | H8: 41758.2 | I8: 15439.677 | K8: EA | L8: 7500 | M8: =J8/L8 -> 0
A9: PerioSciences | B9: 454986.79 | F9: 7898 | G9: MPM DryMax/DrySAP Extra Super Absorbent Drsg, Sterile, 8X8; | H9: 9900 | I9: 9900 | K9: EA | L9: 24000 | M9: =J9/L9 -> 0
A10: MPM Medical, Inc. | B10: 381833.3 | F10: 5662 | G10: MPM Regenecare Wound Gel 0.5 oz, MP00101 | H10: 4900 | I10: 1159.305 | K10: EA | L10: 9600 | M10: =J10/L10 -> 0
A11: OSARTIS GmbH | B11: 327097 | F11: 5440 | G11: MPM Regenecare HA Gel 0.5oz. MP00112 | H11: 7700 | I11: 4408.87 | K11: EA | L11: 50000 | M11: =J11/L11 -> 0
A12: EMED Technologies Corp | B12: 244132 | F12: 5666 | G12: MPM RadiaPlex Rx Gel 6oz. MP00106 | H12: 9364.4 | I12: 3877.9602 | K12: EA | L12: 30000 | M12: =J12/L12 -> 0
A13: Harmac Medical Products, Inc | B13: 233946 | F13: 5859 | G13: MPM MP00990 DRY VEIL CONTACT LAYER 36"X36" (48ea/CS) | H13: 20000 | I13: 8474.79 | K13: EA | L13: 11250 | M13: =J13/L13 -> 0
A14: The Pause Life Supplements, LLC | B14: 213500 | F14: 3424 | G14: MPM Cool Magic Gel Sheet 6.0"x8.0" OL MP00208 | H14: 126000 | I14: 28533.94 | K14: EA | L14: 11250 | M14: =J14/L14 -> 0
A15: Lavipharm SA | B15: 213049 | F15: 5670 | G15: MPM Regenecare HA Spray 4 fl.oz. MP00117 | H15: 17912.7 | I15: 6002.2855 | K15: EA | L15: 14000 | M15: =J15/L15 -> 0
A16: KCII-IRE-IRM | B16: 168138 | F16: 3752 | G16: MPM 4 x 5 THIN FILM DRESSING STERILE MP00470 | H16: 59660 | I16: 13688.842 | K16: EA | L16: 7500 | M16: =J16/L16 -> 0
A17: Freudenberg Performance Materials LP | B17: 163000 | F17: N-4009 | G17: Artwork Prep/Plate Fee(s) | H17: 250 | I17: #N/A | K17: EA | L17: 6250 | M17: =J17/L17 -> 0
A18: Iotech International | B18: 159900 | F18: 3423 | G18: MPM Cool Magic Gel Sheet 3.75"x3.75" OL MP00206 | H18: 49680 | I18: 13616.376 | K18: EA | L18: 22500 | M18: =J18/L18 -> 0
A19: Argentum Medical, LLC | B19: 154517.22 | E19: Harmac Medical Products, Inc | F19: 3958 | G19: Harmac Filter Disc P3113306 Rev E | H19: 58320 | I19: 30460.968 | K19: EA | L19: 76000 | M19: =J19/L19 -> 0 | N19: 76000 | O19: 75000 | P19: 45000 | Q19: 60000
A20: Orora Business Service Center | B20: 105010.99 | F20: 7236 | G20: HARMAC PRTD DRAPE ASSEMBLY W/LABEL - P3113251 Rev C. | H20: 127728 | I20: 70513.68 | K20: CS | L20: 1307 | M20: =J20/L20 -> 0 | N20: 6330 | O20: 6250 | Q20: 6250 | R20: 3750
A21: McKesson Medical Surgical | B21: 104484 | G21: HARMAC PRTD DRAPE ASSEMBLY W/LABEL - P3113251 Rev B. | H21: 47898 | I21: 26442.63 | K21: EA | L21: 60000 | M21: =J21/L21 -> 0 | O21: 60000 | Q21: 60000
A22: O&M Halyard, Inc | B22: 87300 | E22: Iotech International | F22: 7558 | G22: ioTech ioRinse AC 1 liter | H22: 25500 | I22: 19670.865 | K22: CS | N22: 6330 | Q22: 200
A23: Eurofins CRL Cosmetics, Inc | B23: 70050 | F23: 7559 | G23: ioTech ioRinse AC 16oz | H23: 23550 | I23: 17667.93 | K23: EA | L23: 86400 | M23: =J23/L23 -> 0 | N23: 28800 | O23: 90000 | Q23: 30000 | S23: 30000
A24: Centurion Medical Products Corp | B24: 58663.5 | F24: 7560 | G24: ioTech ioRinse Ultra 1 liter | H24: 38250 | I24: 30483.112 | K24: EA | L24: 75000 | M24: =J24/L24 -> 0
A25: Mingguang Glory Sun Precision Technology Co., Ltd. | B25: 46800 | F25: 7561 | G25: ioTech ioRinse Ultra 16 oz | H25: 23550 | I25: 18308.985 | K25: EA | L25: 11874 | M25: =J25/L25 -> 0
A26: Implus LLC | B26: 46800 | F26: 7905 | G26: Iotech MR-HA- US 1L | H26: 25500 | I26: 3520.155 | K26: EA | L26: 10000 | M26: =J26/L26 -> 0 | Q26: 10000
A27: Implus Canada | B27: 45240 | F27: 7906 | G27: Iotech STR-HA 16oz | H27: 23550 | I27: 8342.355 | K27: EA | L27: 864 | M27: =J27/L27 -> 0
A28: Remedium Healthcare Products, LLC | B28: 43800 | E28: Patient Recovery | F28: 7486 | G28: CARDINAL HEALTH TELFA ADHESIVE DRESSING 3"x4" 7643 | H28: 466689.6 | I28: 244230.07 | K28: EA | L28: 1212 | M28: =J28/L28 -> 0
A29: Clyra Medical Technologies, Inc. | B29: 38520 | F29: 7482 | G29: CARDINAL HEALTH TELFA MINI ISLAND DRESSING 2"x3.75" 7539LF | H29: 311866.8 | I29: 39209.463 | K29: EA | L29: 852 | M29: =J29/L29 -> 0
A30: KOB Medical Devices (Deutschland)GmbH | B30: 38500 | F30: 7487 | G30: CARDINAL HEALTH TELFA ADHESIVE DRESSING 2"x3" 6017 | H30: 323712 | I30: 166643.73 | K30: EA | N30: 25000 | Q30: 9000
A31: Medline Assembly Slovakia S.R.O | B31: 37223 | F31: 7488 | G31: CARDINAL HEALTH TELFA NON-ADHERENT DRESSING 3"x4" 2132 | H31: 552096 | I31: 64155.12 | K31: EA | L31: 37500 | M31: =J31/L31 -> 0 | O31: 37500 | R31: 45000
A32: Medline Assembly France SAS | B32: 31554 | F32: 7489 | G32: CARDINAL HEALTH TELFA NON-ADHERENT DRESSING 2"x3" 1961 | H32: 194400 | I32: 42425.865 | K32: EA | L32: 76000 | M32: =J32/L32 -> 0 | N32: 76000 | O32: 75000 | R32: 90000
A33: NAWA, Inc | B33: 30000 | E33: URGO Medical | F33: N-4001 | H33: 58053 | I33: #N/A | K33: EA | L33: 9270 | M33: =J33/L33 -> 0
A34: Turn Therapeutics | B34: 27190 | F34: 7153 | G34: URGO - VASHE 250 ml Flip Top 00313 | H34: 876095.04 | I34: 354378.58 | K34: EA | L34: 6624 | M34: =J34/L34 -> 0
A35: The Bloomi Inc | B35: 21250 | F35: 7154 | G35: URGO - VASHE 475 ml Flip Top 00314 | H35: 77700 | I35: 36058.83 | K35: EA | L35: 4800 | M35: =J35/L35 -> 0
A36: Nexgel | B36: 13264.83 | F36: 7159 | G36: URGO - VASHE 250 ml OTC Flip Top 00405 | H36: 9757.8 | I36: 4113.4181 | K36: EA
A37: Advanced Science Laboratories Inc | B37: 12733.6 | F37: 7152 | G37: URGO - VASHE 118 ml Flip Top 00312 | H37: 504422.64 | I37: 205928.04 | K37: EA | L37: 4128 | M37: =J37/L37 -> 0
A38: DeRoyal Accounts Payable Dept | B38: 11088 | F38: 7155 | G38: URGO - VASHE 250 ml Instill 00316 | H38: 43382.64 | I38: 29143.008 | K38: EA | L38: 60000 | M38: =J38/L38 -> 0 | R38: 60000
A39: Monaderm | B39: 6560 | F39: 7156 | G39: URGO - VASHE 475 ml Instill 00317 | H39: 281940 | I39: 178209.61 | K39: CS | L39: 7500 | M39: =J39/L39 -> 0 | N39: 8000 | O39: 7500 | R39: 6250 | U39: 3750
A40: DermaClip US, LLC | B40: 2039.73 | F40: N-4009 | G40: Artwork Prep/Plate Fee(s) | H40: 1200 | I40: #N/A | K40: EA | L40: 45000 | M40: =J40/L40 -> 0 | O40: 60000 | T40: 50000
...

Sheet Detail1
A1: Details for Total - ItemSalesClassCode: Default , ItemCode: N-4001 (+)
A3: ScheduledShipDate | B3: PromisedShipDate | C3: SONumber | D3: LineNumber | E3: ShipToCode | F3: ItemCode | G3: ItemDescription | H3: OrderQuantity | I3: UnitPrice | J3: ExtendedLineAmount | K3: CustomerCode | L3: ItemSalesClassCode | M3: DropShip | N3: SOTypeCode | O3: FinalDestination | P3: CustomerName | Q3: ShipToAddress1 | R3: ShipToAddress2 | S3: ShipToStateCode | T3: ShipToZip | U3: ParentDocumentNumber | V3: Weight | W3: OrderMessage | X3: ShipToName | Y3: ShipToCity | Z3: ShippingInstructions | AA3: WarehouseCode | AB3: WarehouseName
